Workbook

Sheet Input
A1: Input parameter - Hand grip dynamometer (CZL 601 80 kg + HX711)
A2: Legenda: sel BIRU dengan latar KUNING = input yang boleh diubah. Semua sheet lain berisi rumus dan ikut berubah. Sumber: DS-LC1 dan DS-HX1 di ds-library.md ([4]-[6] load cell, [2] Avia).
A3: Parameter | B3: Nilai | C3: Satuan | D3: Sumber / catatan
A4: Sensitivitas load cell (S) | B4: 2 | C4: mV/V | D4: Eagle Weigh [5]: 2,0 +-0,15 mV/V; nominal
A5: Kapasitas load cell | B5: 80 | C5: kg | D5: Eagle Weigh [5]
A6: Beban maksimum yang dipakai | B6: 70 | C6: kgf | D6: Asumsi proyek: pria muda maks sekitar 59 kgf (Gotthelf) + margin
A7: Beban genggam tipikal (untuk % galat) | B7: 30 | C7: kgf | D7: Wanita 20-24 th rata-rata 31,7 kgf (Gotthelf)
A8: Resistansi masukan jembatan | B8: 400 | C8: ohm | D8: GJ Impex [6]: 400 +-10; vendor 401 +-10; ukur saat tiba
A9: Tegangan eksitasi E+ (V_exc) | B9: 5 | C9: V | D9: Ukur di papan. Papan cacat: sekitar 4,3 V pada catu 5 V; catu 3,3 V: isi 3,3
A10: AVDD HX711 | B10: 5 | C10: V | D10: Ukur; harus sama dengan catu modul
A11: Gain kanal A | B11: 128 | C11: - | D11: Avia [2]: 128 atau 64
A12: Noise masukan 10 SPS | B12: 50 | C12: nV rms | D12: Avia [2], gain 128
A13: Noise masukan 80 SPS | B13: 90 | C13: nV rms | D13: Avia [2], gain 128
A14: Laju data terpilih | B14: 10 | C14: SPS | D14: 10 (bawaan papan) atau 80
A15: Lebar kode ADC | B15: 24 | C15: bit | D15: Avia [2]
... A32: Jumlah pembacaan awal dibuang | B32: 4 | C32: sampel | D32: Settling 400 ms pada 10 Hz

Sheet Hitung
A1: Perhitungan utama (semua rumus; ubah nilai di sheet Input)
A2: Besaran | B2: Nilai | C2: Satuan | D2: Rumus / arti
A3: 1. Sinyal jembatan
A4: Keluaran jembatan pada skala penuh | B4: =Input!$B$4*Input!$B$9 -> 10 | C4: mV | D4: S x V_exc
A5: Keluaran pada beban maksimum | B5: =B4*Input!$B$6/Input!$B$5 -> 8.75 | C5: mV | D5: S x V_exc x F/F_rated (kgf dianggap sama dengan kg)
A6: Sensitivitas absolut | B6: =B4*1000000/(Input!$B$5*1000) -> 125 | C6: nV/g | D6: Pengubah noise ke gram
A7: 2. Rentang ADC
A8: Skala penuh ADC (+-) | B8: =1000*0.5*Input!$B$10/Input!$B$11 -> 19.53125 | C8: mV | D8: 0,5 x AVDD / gain
A9: Pemakaian rentang pada kapasitas penuh | B9: =B4/B8 -> 0.512 | C9: - | D9: Saturasi jika > 1
A10: Pemakaian rentang pada beban maksimum | B10: =B5/B8 -> 0.448 | C10: -
A11: Pemakaian pada overload aman | B11: =B9*Input!$B$18/100 -> 0.6144 | C11: -
A12: Pemakaian pada overload destruktif | B12: =B9*Input!$B$19/100 -> 0.768 | C12: -
A13: Status saturasi | B13: =IF(B12<1,"AMAN","SATURASI") -> AMAN | C13: - | D13: Pada overload destruktif
A14: 3. Common-mode
A15: Titik tengah jembatan | B15: =Input!$B$9/2 -> 2.5 | C15: V | D15: Perkiraan: E+/2
A16: Batas bawah | B16: =Input!$B$16 -> 1.2 | C16: V | D16: AGND + 1,2
A17: Batas atas | B17: =Input!$B$10-Input!$B$17 -> 3.7 | C17: V | D17: AVDD - 1,3
A18: Status | B18: =IF(AND(B15>=B16,B15<=B17),"LULUS","CEK") -> LULUS | C18: -
A19: 4. Hitungan ADC (counts)
A20: Hitungan pada kapasitas penuh | B20: =B9*2^(Input!$B$15-1) -> 4294967.3 | C20: count | D20: Pemakaian x 2^23
A21: Faktor skala ideal | B21: =B20/(Input!$B$5*1000) -> 53.687091 | C21: count/g | D21: Bandingkan dengan hasil kalibrasi
A22: LSB ideal | B22: =1000/B21 -> 18.626451 | C22: mg | D22: Resolusi kuantisasi
A23: 5. Noise
A24: Noise rms pada laju terpilih | B24: =IF(Input!$B$14=80,Input!$B$13,Input!$B$12)/B6 -> 0.4 | C24: g rms | D24: nV / (nV/g)
A25: Noise 10 SPS | B25: =Input!$B$12/B6 -> 0.4 | C25: g rms
A26: Noise 80 SPS | B26: =Input!$B$13/B6 -> 0.72 | C26: g rms
A27: Noise dalam count (laju terpilih) | B27: =B24*B21 -> 21.474836 | C27: count rms
A28: Noise puncak-ke-puncak (6,6 sigma) | B28: =6.6*B24 -> 2.64 | C28: g
A29: Bit bebas-noise pada beban maksimum | B29: =LOG(Input!$B$6*1000/B28,2) -> 14.694529 | C29: bit | D29: log2(rentang / p-p)
A30: 6. Rata-rata dan waktu
A31: Interval sampel | B31: =1000/Input!$B$14 -> 100 | C31: ms
A32: Sampel selama tahan | B32: =Input!$B$14*Input!$B$29 -> 40 | C32: sampel
A33: Waktu pembuangan pembacaan awal | B33: =Input!$B$32*B31 -> 400 | C33: ms
A34: Noise setelah rata-rata 1 s | B34: =B24/SQRT(Input!$B$14) -> 0.12649111 | C34: g rms | D34: sigma/akar N; hanya jika noise putih
A35: Noise setelah rata-rata selama tahan | B35: =B24/SQRT(B32) -> 0.063245553 | C35: g rms
A36: 7. Margin beban
A37: Beban maksimum / kapasitas | B37: =Input!$B$6/Input!$B$5 -> 0.875 | C37: -
A38: Batas aman mekanis | B38: =Input!$B$5*Input!$B$18/100 -> 96 | C38: kgf | D38: Konservatif
A39: Margin terhadap batas aman | B39: =B38/Input!$B$6 -> 1.3714286 | C39: x
A40: Batas destruktif | B40: =Input!$B$5*Input!$B$19/100 -> 120 | C40: kgf
...

Sheet Kalibrasi
A1: Kalibrasi: regresi linear massa terhadap hitungan ADC
A2: Legenda: kolom A-B (biru, kuning) diisi dari uji kalibrasi. Data di bawah adalah CONTOH rekaan untuk memperlihatkan format, BUKAN hasil ukur. Hapus dan ganti dengan data Anda.
A3: Massa (kg) | B3: Hitungan ADC (rata-rata) | C3: Prediksi (kg) | D3: Residu (g)
A4: 0 | B4: 120040 | C4: =($B4-$G$7)*$G$6/1000 -> -0.00079464759 | D4: =(C4-A4)*1000 -> -0.79464759 | F4: Hasil | G4: Nilai | H4: Satuan
A5: 5 | B5: 388520 | C5: =($B5-$G$7)*$G$6/1000 -> 5.0001341 | D5: =(C5-A5)*1000 -> 0.13406605 | F5: Kemiringan (kg per count) | G5: =SLOPE($A$4:$A$9,$B$4:$B$9) -> 1.862682e-05 | H5: kg/count
A6: 10 | B6: 657010 | C6: =($B6-$G$7)*$G$6/1000 -> 10.001249 | D6: =(C6-A6)*1000 -> 1.2490479 | F6: Faktor skala k | G6: =G5*1000 -> 0.01862682 | H6: g/count
A7: 15 | B7: 925350 | C7: =($B7-$G$7)*$G$6/1000 -> 14.99957 | D7: =(C7-A7)*1000 -> -0.42999329 | F7: Offset N0 (count pada 0 kg) | G7: =-INTERCEPT($A$4:$A$9,$B$4:$B$9)/SLOPE($A$4:$A$9,$B$4:$B$9) -> 120082.66 | H7: count
A8: 20 | B8: 1193890 | C8: =($B8-$G$7)*$G$6/1000 -> 20.001616 | D8: =(C8-A8)*1000 -> 1.6163296 | F8: R kuadrat | G8: =RSQ($A$4:$A$9,$B$4:$B$9) -> 0.99999998 | H8: -
A9: 22 | B9: 1301080 | C9: =($B9-$G$7)*$G$6/1000 -> 21.998225 | D9: =(C9-A9)*1000 -> -1.7748027 | F9: Galat baku regresi | G9: =STEYX($A$4:$A$9,$B$4:$B$9)*1000 -> 1.4280143 | H9: g
F10: Galat baku kemiringan (relatif) | G10: =INDEX(LINEST($A$4:$A$9,$B$4:$B$9,TRUE(),TRUE()),2,1)/SLOPE($A$4:$A$9,$B$4:$B$9) -> 7.4238928e-05 | H10: -
F11: Count/g terukur | G11: =1/(G6) -> 53.686028 | H11: count/g
F12: Selisih dari faktor ideal (Hitung) | G12: =G11/Hitung!B21-1 -> -1.9799721e-05 | H12: -
A14: Cara pakai: W(g) = (N - N0) x k. Tare menyetel N0 ulang sebelum tiap pengukuran. Titik di antara 3-5 massa mati, naik dan turun (histeresis).

Sheet Galat
A1: Anggaran galat (dalam gram pada kapasitas penuh)
A2: Kolom "Masuk RSS" (biru, kuning): 1 = ikut digabung, 0 = dihapus oleh tare atau kalibrasi. Ubah sesuai prosedur.
A3: Sumber galat | B3: Besar (g) | C3: Masuk RSS (1/0) | D3: Dihapus oleh | E3: Catatan
A4: Error gabungan load cell | B4: =Input!$B$5*1000*Input!$B$20/100 -> 24 | C4: 1 | D4: - | E4: Linearitas + histeresis + repeatabilitas; nilai Eagle Weigh
A5: Zero balance | B5: =Input!$B$5*1000*Input!$B$22/100 -> 800 | C5: 0 | D5: Tare | E5: Offset awal
A6: Toleransi sensitivitas | B6: =Input!$B$5*1000*Input!$B$23/Input!$B$4 -> 6000 | C6: 0 | D6: Kalibrasi | E6: +-0,15/2,0 = 7,5% dari skala
A7: Efek suhu load cell | B7: =Input!$B$5*1000*Input!$B$24/100*Input!$B$25/10 -> 24 | C7: 1 | D7: - | E7: Nol + span, kasus terburuk
A8: Drift offset HX711 | B8: =Input!$B$26*Input!$B$25/Hitung!B6 -> 0.48 | C8: 1 | D8: - | E8: nV/C x dT / (nV/g)
A9: Noise HX711 (laju terpilih) | B9: =Hitung!B24 -> 0.4 | C9: 1 | D9: - | E9: 1 sigma
A10: Creep selama 30 menit | B10: =Input!$B$5*1000*Input!$B$21/100 -> 20 | C10: 0 | D10: Durasi tahan beberapa detik | E10: Tidak relevan untuk genggam 3-5 s; relevan untuk beban kalibrasi lama
A11: Efek kemiringan housing | B11: =Input!$B$30*(1-COS(RADIANS(Input!$B$31)))*1000 -> 140 | C11: 0 | D11: Tare pada postur akhir | E11: m x (1 - cos teta)
A13: Gabungan RSS (yang ikut) | B13: =SQRT(SUMPRODUCT(C4:C11,B4:B11^2)) -> 33.946876 | E13: Akar jumlah kuadrat
A14: Gabungan sebagai % kapasitas | B14: =B13/(Input!$B$5*1000) -> 0.00042433595
A15: Gabungan pada beban tipikal (% pembacaan) | B15: =B13/(Input!$B$7*1000) -> 0.0011315625 | E15: Beban tipikal dari Input
A16: Gabungan pada beban maksimum (% pembacaan) | B16: =B13/(Input!$B$6*1000) -> 0.00048495537
A18: Catatan: ini batas bawah ketidakpastian. Massa kalibrasi, pemasangan, dan beban off-centre menambah galat dan harus diukur.
